[2025-09-08T15:25:21.253+0000] {local_task_job_runner.py:123} INFO - ::group::Pre task execution logs
[2025-09-08T15:25:21.265+0000] {taskinstance.py:2612} INFO - Dependencies all met for dep_context=non-requeueable deps ti=<TaskInstance: executing_sql_pipeline.create_table scheduled__2025-09-07T00:00:00+00:00 [queued]>
[2025-09-08T15:25:21.272+0000] {taskinstance.py:2612} INFO - Dependencies all met for dep_context=requeueable deps ti=<TaskInstance: executing_sql_pipeline.create_table scheduled__2025-09-07T00:00:00+00:00 [queued]>
[2025-09-08T15:25:21.272+0000] {taskinstance.py:2865} INFO - Starting attempt 1 of 1
[2025-09-08T15:25:21.293+0000] {taskinstance.py:2888} INFO - Executing <Task(SqliteOperator): create_table> on 2025-09-07 00:00:00+00:00
[2025-09-08T15:25:21.297+0000] {standard_task_runner.py:72} INFO - Started process 12479 to run task
[2025-09-08T15:25:21.299+0000] {standard_task_runner.py:104} INFO - Running: ['airflow', 'tasks', 'run', 'executing_sql_pipeline', 'create_table', 'scheduled__2025-09-07T00:00:00+00:00', '--job-id', '62', '--raw', '--subdir', 'DAGS_FOLDER/executing_sql_pipeline.py', '--cfg-path', '/tmp/tmp_jbmape7']
[2025-09-08T15:25:21.300+0000] {standard_task_runner.py:105} INFO - Job 62: Subtask create_table
[2025-09-08T15:25:21.327+0000] {task_command.py:467} INFO - Running <TaskInstance: executing_sql_pipeline.create_table scheduled__2025-09-07T00:00:00+00:00 [running]> on host codespaces-9bd7b3
[2025-09-08T15:25:21.385+0000] {taskinstance.py:3131} INFO - Exporting env vars: AIRFLOW_CTX_DAG_OWNER='loonycorn' AIRFLOW_CTX_DAG_ID='executing_sql_pipeline' AIRFLOW_CTX_TASK_ID='create_table' AIRFLOW_CTX_EXECUTION_DATE='2025-09-07T00:00:00+00:00' AIRFLOW_CTX_TRY_NUMBER='1' AIRFLOW_CTX_DAG_RUN_ID='scheduled__2025-09-07T00:00:00+00:00'
[2025-09-08T15:25:21.386+0000] {taskinstance.py:731} INFO - ::endgroup::
[2025-09-08T15:25:21.403+0000] {sql.py:266} INFO - Executing: 
            CREATE TABLE IF NOT EXISTS users (
                    id INTEGER PRIMARY KEY,
                    name VARCHAR(50) NOT NULL,
                    age INTEGER NOT NULL,
                    is_active BOOLEAN DEFAULT true,
                    created_at TIMESTAMP DEFAULT CURRENT_TIMESTAMP
            );
        
[2025-09-08T15:25:21.409+0000] {taskinstance.py:3310} ERROR - Task failed with exception
Traceback (most recent call last):
  File "/usr/local/python/3.12.1/lib/python3.12/site-packages/airflow/models/taskinstance.py", line 767, in _execute_task
    result = _execute_callable(context=context, **execute_callable_kwargs)
             ^^^^^^^^^^^^^^^^^^^^^^^^^^^^^^^^^^^^^^^^^^^^^^^^^^^^^^^^^^^^^
  File "/usr/local/python/3.12.1/lib/python3.12/site-packages/airflow/models/taskinstance.py", line 733, in _execute_callable
    return ExecutionCallableRunner(
           ^^^^^^^^^^^^^^^^^^^^^^^^
  File "/usr/local/python/3.12.1/lib/python3.12/site-packages/airflow/utils/operator_helpers.py", line 252, in run
    return self.func(*args, **kwargs)
           ^^^^^^^^^^^^^^^^^^^^^^^^^^
  File "/usr/local/python/3.12.1/lib/python3.12/site-packages/airflow/models/baseoperator.py", line 406, in wrapper
    return func(self, *args, **kwargs)
           ^^^^^^^^^^^^^^^^^^^^^^^^^^^
  File "/usr/local/python/3.12.1/lib/python3.12/site-packages/airflow/providers/common/sql/operators/sql.py", line 267, in execute
    hook = self.get_db_hook()
           ^^^^^^^^^^^^^^^^^^
  File "/usr/local/python/3.12.1/lib/python3.12/site-packages/airflow/providers/common/sql/operators/sql.py", line 178, in get_db_hook
    return self._hook
           ^^^^^^^^^^
  File "/usr/local/python/3.12.1/lib/python3.12/functools.py", line 995, in __get__
    val = self.func(instance)
          ^^^^^^^^^^^^^^^^^^^
  File "/usr/local/python/3.12.1/lib/python3.12/site-packages/airflow/providers/common/sql/operators/sql.py", line 153, in _hook
    conn = BaseHook.get_connection(conn_id)
           ^^^^^^^^^^^^^^^^^^^^^^^^^^^^^^^^
  File "/usr/local/python/3.12.1/lib/python3.12/site-packages/airflow/hooks/base.py", line 83, in get_connection
    conn = Connection.get_connection_from_secrets(conn_id)
           ^^^^^^^^^^^^^^^^^^^^^^^^^^^^^^^^^^^^^^^^^^^^^^^
  File "/usr/local/python/3.12.1/lib/python3.12/site-packages/airflow/models/connection.py", line 537, in get_connection_from_secrets
    raise AirflowNotFoundException(f"The conn_id `{conn_id}` isn't defined")
airflow.exceptions.AirflowNotFoundException: The conn_id `my_sqlite_conn` isn't defined
[2025-09-08T15:25:21.588+0000] {taskinstance.py:1225} INFO - Marking task as FAILED. dag_id=executing_sql_pipeline, task_id=create_table, run_id=scheduled__2025-09-07T00:00:00+00:00, execution_date=20250907T000000, start_date=20250908T152521, end_date=20250908T152521
[2025-09-08T15:25:21.598+0000] {taskinstance.py:340} INFO - ::group::Post task execution logs
[2025-09-08T15:25:21.598+0000] {standard_task_runner.py:124} ERROR - Failed to execute job 62 for task create_table (The conn_id `my_sqlite_conn` isn't defined; 12479)
Traceback (most recent call last):
  File "/usr/local/python/3.12.1/lib/python3.12/site-packages/airflow/task/task_runner/standard_task_runner.py", line 117, in _start_by_fork
    ret = args.func(args, dag=self.dag)
          ^^^^^^^^^^^^^^^^^^^^^^^^^^^^^
  File "/usr/local/python/3.12.1/lib/python3.12/site-packages/airflow/cli/cli_config.py", line 49, in command
    return func(*args, **kwargs)
           ^^^^^^^^^^^^^^^^^^^^^
  File "/usr/local/python/3.12.1/lib/python3.12/site-packages/airflow/utils/cli.py", line 115, in wrapper
    return f(*args, **kwargs)
           ^^^^^^^^^^^^^^^^^^
  File "/usr/local/python/3.12.1/lib/python3.12/site-packages/airflow/cli/commands/task_command.py", line 483, in task_run
    task_return_code = _run_task_by_selected_method(args, _dag, ti)
                       ^^^^^^^^^^^^^^^^^^^^^^^^^^^^^^^^^^^^^^^^^^^^
  File "/usr/local/python/3.12.1/lib/python3.12/site-packages/airflow/cli/commands/task_command.py", line 256, in _run_task_by_selected_method
    return _run_raw_task(args, ti)
           ^^^^^^^^^^^^^^^^^^^^^^^
  File "/usr/local/python/3.12.1/lib/python3.12/site-packages/airflow/cli/commands/task_command.py", line 341, in _run_raw_task
    return ti._run_raw_task(
           ^^^^^^^^^^^^^^^^^
  File "/usr/local/python/3.12.1/lib/python3.12/site-packages/airflow/utils/session.py", line 97, in wrapper
    return func(*args, session=session, **kwargs)
           ^^^^^^^^^^^^^^^^^^^^^^^^^^^^^^^^^^^^^^
  File "/usr/local/python/3.12.1/lib/python3.12/site-packages/airflow/models/taskinstance.py", line 3004, in _run_raw_task
    return _run_raw_task(
           ^^^^^^^^^^^^^^
  File "/usr/local/python/3.12.1/lib/python3.12/site-packages/airflow/models/taskinstance.py", line 273, in _run_raw_task
    TaskInstance._execute_task_with_callbacks(
  File "/usr/local/python/3.12.1/lib/python3.12/site-packages/airflow/models/taskinstance.py", line 3158, in _execute_task_with_callbacks
    result = self._execute_task(context, task_orig)
             ^^^^^^^^^^^^^^^^^^^^^^^^^^^^^^^^^^^^^^
  File "/usr/local/python/3.12.1/lib/python3.12/site-packages/airflow/models/taskinstance.py", line 3182, in _execute_task
    return _execute_task(self, context, task_orig)
           ^^^^^^^^^^^^^^^^^^^^^^^^^^^^^^^^^^^^^^^
  File "/usr/local/python/3.12.1/lib/python3.12/site-packages/airflow/models/taskinstance.py", line 767, in _execute_task
    result = _execute_callable(context=context, **execute_callable_kwargs)
             ^^^^^^^^^^^^^^^^^^^^^^^^^^^^^^^^^^^^^^^^^^^^^^^^^^^^^^^^^^^^^
  File "/usr/local/python/3.12.1/lib/python3.12/site-packages/airflow/models/taskinstance.py", line 733, in _execute_callable
    return ExecutionCallableRunner(
           ^^^^^^^^^^^^^^^^^^^^^^^^
  File "/usr/local/python/3.12.1/lib/python3.12/site-packages/airflow/utils/operator_helpers.py", line 252, in run
    return self.func(*args, **kwargs)
           ^^^^^^^^^^^^^^^^^^^^^^^^^^
  File "/usr/local/python/3.12.1/lib/python3.12/site-packages/airflow/models/baseoperator.py", line 406, in wrapper
    return func(self, *args, **kwargs)
           ^^^^^^^^^^^^^^^^^^^^^^^^^^^
  File "/usr/local/python/3.12.1/lib/python3.12/site-packages/airflow/providers/common/sql/operators/sql.py", line 267, in execute
    hook = self.get_db_hook()
           ^^^^^^^^^^^^^^^^^^
  File "/usr/local/python/3.12.1/lib/python3.12/site-packages/airflow/providers/common/sql/operators/sql.py", line 178, in get_db_hook
    return self._hook
           ^^^^^^^^^^
  File "/usr/local/python/3.12.1/lib/python3.12/functools.py", line 995, in __get__
    val = self.func(instance)
          ^^^^^^^^^^^^^^^^^^^
  File "/usr/local/python/3.12.1/lib/python3.12/site-packages/airflow/providers/common/sql/operators/sql.py", line 153, in _hook
    conn = BaseHook.get_connection(conn_id)
           ^^^^^^^^^^^^^^^^^^^^^^^^^^^^^^^^
  File "/usr/local/python/3.12.1/lib/python3.12/site-packages/airflow/hooks/base.py", line 83, in get_connection
    conn = Connection.get_connection_from_secrets(conn_id)
           ^^^^^^^^^^^^^^^^^^^^^^^^^^^^^^^^^^^^^^^^^^^^^^^
  File "/usr/local/python/3.12.1/lib/python3.12/site-packages/airflow/models/connection.py", line 537, in get_connection_from_secrets
    raise AirflowNotFoundException(f"The conn_id `{conn_id}` isn't defined")
airflow.exceptions.AirflowNotFoundException: The conn_id `my_sqlite_conn` isn't defined
[2025-09-08T15:25:21.634+0000] {local_task_job_runner.py:266} INFO - Task exited with return code 1
[2025-09-08T15:25:21.646+0000] {taskinstance.py:3900} INFO - 0 downstream tasks scheduled from follow-on schedule check
[2025-09-08T15:25:21.647+0000] {local_task_job_runner.py:245} INFO - ::endgroup::
